<?xml version="1.0" encoding="utf-8"?>
<robot name="psm" xmlns:xacro="http://www.ros.org/wiki/xacro">

  <xacro:macro name="psm" params=" prefix parent_link xyz rpy">
    
    <!-- fixed joint 0 -->
    <joint name="${prefix}rev_joint" type="fixed">
     <parent link="${parent_link}"/>
     <child link="${prefix}base_link"/>
     <origin rpy="${rpy}" xyz="${xyz}"/>
     <axis xyz="0 0 1"/>
    <!-- <limit
       lower="-3.14159"
       upper="3.14159"
       effort="1000"
       velocity="10" /> -->
    </joint>

  <!-- link 0: psm base link -->
  <link
    name="${prefix}base_link">
    <inertial>
      <origin
        xyz="0 -0.17016 -0.085607"
        rpy="0 0 0" />
      <mass
        value="2.0161" />
      <inertia
        ixx="0"
        ixy="0"
        ixz="0"
        iyy="0"
        iyz="0"
        izz="0" />
    </inertial>
    <visual>
      <origin
        xyz="0 0 0"
        rpy="0 0 0" />
      <geometry>
        <mesh
          filename="package://dvrk_description/psm/meshes/base_link.STL" />
      </geometry>
      <material
        name="">
        <color
          rgba="0.89804 0.91765 0.92941 1" />
      </material>
    </visual>
    <collision>
      <origin
        xyz="0 0 0"
        rpy="0 0 0" />
      <geometry>
        <mesh
          filename="package://dvrk_description/psm/meshes/base_link.STL" />
      </geometry>
    </collision>
  </link>

  <!-- link 1: psm yaw_link -->
  <link
    name="${prefix}yaw_link">
    <inertial>
      <origin
        xyz="-0.038769 0 0.041596"
        rpy="0 0 0" />
      <mass
        value="1.4705" />
      <inertia
        ixx="0"
        ixy="0"
        ixz="0"
        iyy="0"
        iyz="0"
        izz="0" />
    </inertial>
    <visual>
      <origin
        xyz="0 0 0"
        rpy="0 0 0" />
      <geometry>
        <mesh
          filename="package://dvrk_description/psm/meshes/yaw_link.STL" />
      </geometry>
      <material
        name="">
        <color
          rgba="0.89804 0.91765 0.92941 1" />
      </material>
    </visual>
    <collision>
      <origin
        xyz="0 0 0"
        rpy="0 0 0" />
      <geometry>
        <mesh
          filename="package://dvrk_description/psm/meshes/yaw_link.STL" />
      </geometry>
    </collision>
  </link>

  <!-- joint 1 psm yaw joint-->
  <joint
    name="${prefix}yaw_joint"
    type="revolute">
    <origin
      xyz="0 0 0"
      rpy="1.5708 -1.5708 0" />
    <parent
      link="${prefix}base_link" />
    <child
      link="${prefix}yaw_link" />
    <axis
      xyz="0 0 1" />
    <!--<limit
      lower="-1.605"
      upper="1.5994"
      effort="1000"
	  velocity="10" /> -->
    <limit lower="-1.5707" upper="1.5707" velocity=".4" effort="1000"/>
  </joint>
  
  <!-- link 2: outer_pitch_back -->
  <link
    name="${prefix}pitch_back_link">
    <inertial>
      <origin
        xyz="-0.011651 -0.036241 0"
        rpy="0 0 0" />
      <mass
        value="0.98494" />
      <inertia
        ixx="0"
        ixy="0"
        ixz="0"
        iyy="0"
        iyz="0"
        izz="0" />
    </inertial>
    <visual>
      <origin
        xyz="0 0 0"
        rpy="0 0 0" />
      <geometry>
        <mesh
          filename="package://dvrk_description/psm/meshes/pitch_back_link.STL" />
      </geometry>
      <material
        name="">
        <color
          rgba="0.89804 0.91765 0.92941 1" />
      </material>
    </visual>
    <collision>
      <origin
        xyz="0 0 0"
        rpy="0 0 0" />
      <geometry>
        <mesh
          filename="package://dvrk_description/psm/meshes/pitch_back_link.STL" />
      </geometry>
    </collision>
  </link>

  <!-- joint 2: pitch_back_joint -->
  <joint
    name="${prefix}pitch_back_joint"
    type="continuous">
    <origin
      xyz="0 0 0.0296"
      rpy="-1.5708 -0.29073 0" />
    <parent
      link="${prefix}yaw_link" />
    <child
      link="${prefix}pitch_back_link" />
    <axis
      xyz="0 0 1" />
	<limit
      lower="-0.93556"
      upper="0.94249"
      effort="1000"
	  velocity="10" />
  </joint>

  <!-- link 3: outer_pitch_back -->
  <link
    name="${prefix}pitch_bottom_link">
    <inertial>
      <origin
        xyz="0.25683 -0.010348 0"
        rpy="0 0 0" />
      <mass
        value="0.44569" />
      <inertia
        ixx="0"
        ixy="0"
        ixz="0"
        iyy="0"
        iyz="0"
        izz="0" />
    </inertial>
    <visual>
      <origin
        xyz="0 0 0"
        rpy="0 0 0" />
      <geometry>
        <mesh
          filename="package://dvrk_description/psm/meshes/pitch_bottom_link.STL" />
      </geometry>
      <material
        name="">
        <color
          rgba="0.89804 0.91765 0.92941 1" />
      </material>
    </visual>
    <collision>
      <origin
        xyz="0 0 0"
        rpy="0 0 0" />
      <geometry>
        <mesh
          filename="package://dvrk_description/psm/meshes/pitch_bottom_link.STL" />
      </geometry>
    </collision>
  </link>

  <!-- joint 3: pitch_bottom_joint -->
  <joint
    name="${prefix}pitch_bottom_joint"
    type="continuous">
    <origin
      xyz="0.15 0 0"
      rpy="0 0 1.8615" />
    <parent
      link="${prefix}pitch_back_link" />
    <child
      link="${prefix}pitch_bottom_link" />
    <axis
      xyz="0 0 1" />
    <limit
      lower="-0.94249"
      upper="0.93556"
      effort="1000"
	  velocity="10" />
    <mimic joint="${prefix}pitch_back_joint" multiplier="-1"/>
  </joint>

  <!-- link 4: pitch_end_link -->
  <link
    name="${prefix}pitch_end_link">
    <inertial>
      <origin
        xyz="-0.0019293 -0.13613 0"
        rpy="0 0 0" />
      <mass
        value="2.091" />
      <inertia
        ixx="0"
        ixy="0"
        ixz="0"
        iyy="0"
        iyz="0"
        izz="0" />
    </inertial>
    <visual>
      <origin
        xyz="0 0 0"
        rpy="0 0 0" />
      <geometry>
        <mesh
          filename="package://dvrk_description/psm/meshes/pitch_end_link.STL" />
      </geometry>
      <material
        name="">
        <color
          rgba="0.89804 0.91765 0.92941 1" />
      </material>
    </visual>
    <collision>
      <origin
        xyz="0 0 0"
        rpy="0 0 0" />
      <geometry>
        <mesh
          filename="package://dvrk_description/psm/meshes/pitch_end_link.STL" />
      </geometry>
    </collision>
  </link>

  <!-- joint 4: pitch_end_joint -->
  <joint
    name="${prefix}pitch_end_joint"
    type="continuous">
    <origin
      xyz="0.516 0 0"
      rpy="0 0 0" />
    <parent
      link="${prefix}pitch_bottom_link" />
    <child
      link="${prefix}pitch_end_link" />
    <axis
      xyz="0 0 1" />
    <limit
      lower="-0.93556"
      upper="0.94249"
      effort="1000"
	  velocity="10" />
    <mimic joint="${prefix}pitch_back_joint" multiplier="1"/>
  </joint>

  <!-- link 5: main_insertion_link -->
  <link
    name="${prefix}main_insertion_link">
    <inertial>
      <origin
        xyz="0.0040563 -0.00010934 0.0098616"
        rpy="0 0 0" />
      <mass
        value="0.22491" />
      <inertia
        ixx="0"
        ixy="0"
        ixz="0"
        iyy="0"
        iyz="0"
        izz="0" />
    </inertial>
    <visual>
      <origin
        xyz="0 0 0"
        rpy="0 0 1.5708" />
      <geometry>
        <mesh
          filename="package://dvrk_description/psm/meshes/main_insertion_link.STL" />
      </geometry>
      <material
        name="">
        <color
          rgba="1 0.55686 0.058824 0.4" />
      </material>
    </visual>
    <collision>
      <origin
        xyz="0 0 0"
        rpy="0 0 0" />
      <geometry>
        <mesh
          filename="package://dvrk_description/psm/meshes/main_insertion_link.STL" />
      </geometry>
    </collision>
  </link>

  <!-- joint 5: main_insertion_joint -->
  <joint
    name="${prefix}main_insertion_joint"
    type="prismatic">
    <origin
      xyz="0.043 -0.28809 0"
      rpy="1.5708 1.5708 3.1416" />
    <parent
      link="${prefix}pitch_end_link" />
    <child
      link="${prefix}main_insertion_link" />
    <axis
      xyz="0 0 1" />
    <limit
      lower="0"
      upper="0.24"
      effort="1000"
	    velocity="1" />
  </joint>

  <!-- link 6: tool_roll_link -->
  <link
    name="${prefix}tool_roll_link">
    <inertial>
      <origin
        xyz="0 0 -0.0058234"
        rpy="0 0 0" />
      <mass
        value="0.00033225" />
      <inertia
        ixx="0"
        ixy="0"
        ixz="0"
        iyy="0"
        iyz="0"
        izz="0" />
    </inertial>
    <visual>
      <origin
        xyz="0 0 0"
        rpy="0 0 0" />
      <geometry>
        <mesh
          filename="package://dvrk_description/psm/meshes/tool_roll_link.STL" />
      </geometry>
      <material
        name="">
        <color
          rgba="0.79608 0.82353 0.93725 1" />
      </material>
    </visual>
    <collision>
      <origin
        xyz="0 0 0"
        rpy="0 0 0" />
      <geometry>
        <mesh
          filename="package://dvrk_description/psm/meshes/tool_roll_link.STL" />
      </geometry>
    </collision>
  </link>

  <!-- joint 6: tool_roll_joint -->
  <joint
    name="${prefix}tool_roll_joint"
    type="revolute">
    <origin
      xyz="0 0 0.4162"
      rpy="0 0 -1.5708" />
    <parent
      link="${prefix}main_insertion_link" />
    <child
      link="${prefix}tool_roll_link" />
    <axis
      xyz="0 0 1" />
    <!-- <limit
      lower="-3.14159"
      upper="3.14159"
      effort="1000"
      velocity="10" /> -->
    <limit lower="-2.2689" upper="2.2689" velocity=".4" effort="1000"/>
  </joint>

  <!-- link 7: tool_pitch_link -->
  <link
    name="${prefix}tool_pitch_link">
    <inertial>
      <origin
        xyz="0.0035763 0 0"
        rpy="0 0 0" />
      <mass
        value="0.00025784" />
      <inertia
        ixx="0"
        ixy="0"
        ixz="0"
        iyy="0"
        iyz="0"
        izz="0" />
    </inertial>
    <visual>
      <origin
        xyz="0 0 0"
        rpy="0 0 0" />
      <geometry>
        <mesh
          filename="package://dvrk_description/psm/meshes/tool_pitch_link.STL" />
      </geometry>
      <material
        name="">
        <color
          rgba="0.79608 0.82353 0.93725 1" />
      </material>
    </visual>
    <collision>
      <origin
        xyz="0 0 0"
        rpy="0 0 0" />
      <geometry>
        <mesh
          filename="package://dvrk_description/psm/meshes/tool_pitch_link.STL" />
      </geometry>
    </collision>
  </link>

  <!-- joint 7: tool_pitch_joint -->
  <joint
    name="${prefix}tool_pitch_joint"
    type="revolute">
    <origin
      xyz="0 0 0"
      rpy="1.5708 -1.5708 3.1416" />
    <parent
      link="${prefix}tool_roll_link" />
    <child
      link="${prefix}tool_pitch_link" />
    <axis
      xyz="0 0 1" />
    <limit
      lower="-1.5708"
      upper="1.5708"
      effort="1000"
      velocity="10" />
  </joint>

  <!-- link 8: tool_yaw_link -->
  <link
    name="${prefix}tool_yaw_link">
    <inertial>
      <origin
        xyz="0 0 0"
        rpy="0 0 0" />
      <mass
        value="0" />
      <inertia
        ixx="0"
        ixy="0"
        ixz="0"
        iyy="0"
        iyz="0"
        izz="0" />
    </inertial>
    <visual>
      <origin
        xyz="0 0 0"
        rpy="0 0 0" />
      <geometry>
        <mesh
          filename="package://dvrk_description/psm/meshes/tool_yaw_link.STL" />
      </geometry>
      <material
        name="">
        <color
          rgba="0.79608 0.82353 0.93725 1" />
      </material>
    </visual>
    <collision>
      <origin
        xyz="0 0 0"
        rpy="0 0 0" />
      <geometry>
        <mesh
          filename="package://dvrk_description/psm/meshes/tool_yaw_link.STL" />
      </geometry>
    </collision>
  </link>

  <!-- joint 8: tool_yaw_joint -->
  <joint
    name="${prefix}tool_yaw_joint"
    type="revolute">
    <origin
      xyz="0.0091 0 0"
      rpy="1.5708 -1.5708 3.1416" />
    <parent
      link="${prefix}tool_pitch_link" />
    <child
      link="${prefix}tool_yaw_link" />
    <axis
      xyz="0 0 1" />
    <!-- <limit
      lower="-1.5708"
      upper="1.5708"
      effort="1000"
	    velocity="10" /> -->
    <limit lower="-1.3963" upper="1.3963" velocity=".4" effort="1000"/>
  </joint>

  <!-- link 9: tool_gripper1_link -->
  <link
    name="${prefix}tool_gripper1_link">
    <inertial>
      <origin
        xyz="0.00019605 0.001435 -0.00088478"
        rpy="0 0 0" />
      <mass
        value="0" />
      <inertia
        ixx="0"
        ixy="0"
        ixz="0"
        iyy="0"
        iyz="0"
        izz="0" />
    </inertial>
    <visual>
      <origin
        xyz="0 0 0"
        rpy="0 0 0" />
      <geometry>
        <mesh
          filename="package://dvrk_description/psm/meshes/tool_gripper1_link.STL" />
      </geometry>
      <material
        name="">
        <color
          rgba="0.79608 0.82353 0.93725 1" />
      </material>
    </visual>
    <collision>
      <origin
        xyz="0 0 0"
        rpy="0 0 0" />
      <geometry>
        <mesh
          filename="package://dvrk_description/psm/meshes/tool_gripper1_link.STL" />
      </geometry>
    </collision>
  </link>

  <!-- joint 9: tool_gripper1_joint -->
  <joint
    name="${prefix}tool_gripper1_joint"
    type="revolute">
    <origin
      xyz="0 0 0"
      rpy="0 0 0" />
    <parent
      link="${prefix}tool_yaw_link" />
    <child
      link="${prefix}tool_gripper1_link" />
    <axis
      xyz="0 0 1" />
      <mimic joint="${prefix}tool_gripper2_joint" multiplier="-1"/>
    <!-- <limit
      lower="0"
      upper="1"
      effort="0"
	    velocity="0" /> -->
    <limit lower="-1.5707" upper="1.5707" velocity=".4" effort="1000"/>
  </joint>

  <!-- link 10: tool_gripper2_link -->
  <link
    name="${prefix}tool_gripper2_link">
    <inertial>
      <origin
        xyz="-0.00019605 0.001435 0.00088478"
        rpy="0 0 0" />
      <mass
        value="0" />
      <inertia
        ixx="0"
        ixy="0"
        ixz="0"
        iyy="0"
        iyz="0"
        izz="0" />
    </inertial>
    <visual>
      <origin
        xyz="0 0 0"
        rpy="0 0 0" />
      <geometry>
        <mesh
          filename="package://dvrk_description/psm/meshes/tool_gripper2_link.STL" />
      </geometry>
      <material
        name="">
        <color
          rgba="0.79608 0.82353 0.93725 1" />
      </material>
    </visual>
    <collision>
      <origin
        xyz="0 0 0"
        rpy="0 0 0" />
      <geometry>
        <mesh
          filename="package://dvrk_description/psm/meshes/tool_gripper2_link.STL" />
      </geometry>
    </collision>
  </link>

  <!-- joint 10: tool_gripper2_joint -->
  <joint
    name="${prefix}tool_gripper2_joint"
    type="revolute">
    <origin
      xyz="0 0 0"
      rpy="0 0 0" />
    <parent
      link="${prefix}tool_yaw_link" />
    <child
      link="${prefix}tool_gripper2_link" />
    <axis
      xyz="0 0 1" />
    <!-- <limit
      lower="0"
      upper="1"
      effort="0"
	    velocity="0" /> -->
    <limit lower="-1.5707" upper="1.5707" velocity=".4" effort="1000"/>
  </joint>

  <!-- link 11: pitch_top_link -->
  <link
    name="${prefix}pitch_top_link">
    <inertial>
      <origin
        xyz="0.31246 -0.00056566 0"
        rpy="0 0 0" />
      <mass
        value="0.17841" />
      <inertia
        ixx="0"
        ixy="0"
        ixz="0"
        iyy="0"
        iyz="0"
        izz="0" />
    </inertial>
    <visual>
      <origin
        xyz="0 0 0"
        rpy="0 0 0" />
      <geometry>
        <mesh
          filename="package://dvrk_description/psm/meshes/pitch_top_link.STL" />
      </geometry>
      <material
        name="">
        <color
          rgba="0.89804 0.91765 0.92941 1" />
      </material>
    </visual>
    <collision>
      <origin
        xyz="0 0 0"
        rpy="0 0 0" />
      <geometry>
        <mesh
          filename="package://dvrk_description/psm/meshes/pitch_top_link.STL" />
      </geometry>
    </collision>
  </link>

  <!-- joint 11: pitch_top_joint -->
  <joint
    name="${prefix}pitch_top_joint"
    type="continuous">
    <origin
      xyz="0.18366 0.014121 0"
      rpy="0 0 1.8615" />
    <parent
      link="${prefix}pitch_back_link" />
    <child
      link="${prefix}pitch_top_link" />
    <axis
      xyz="0 0 1" />
    <limit
      lower="-0.94249"
      upper="0.93556"
      effort="1000"
	  velocity="10" />
    <mimic joint="${prefix}pitch_back_joint" multiplier="-1"/>
  </joint>

  <!-- link 12: pitch_front_link -->
  <link
    name="${prefix}pitch_front_link">
    <inertial>
      <origin
        xyz="0.096269 0 0.047551"
        rpy="0 0 0" />
      <mass
        value="0.074425" />
      <inertia
        ixx="0"
        ixy="0"
        ixz="0"
        iyy="0"
        iyz="0"
        izz="0" />
    </inertial>
    <visual>
      <origin
        xyz="0 0 0"
        rpy="0 0 0" />
      <geometry>
        <mesh
          filename="package://dvrk_description/psm/meshes/pitch_front_link.STL" />
      </geometry>
      <material
        name="">
        <color
          rgba="0.89804 0.91765 0.92941 1" />
      </material>
    </visual>
    <collision>
      <origin
        xyz="0 0 0"
        rpy="0 0 0" />
      <geometry>
        <mesh
          filename="package://dvrk_description/psm/meshes/pitch_front_link.STL" />
      </geometry>
    </collision>
  </link>

  <!-- joint 12: pitch_front_joint -->
  <joint
    name="${prefix}pitch_front_joint"
    type="continuous">
    <origin
      xyz="0 0 -0.0664"
      rpy="-1.5708 -0.29073 0" />
    <parent
      link="${prefix}yaw_link" />
    <child
      link="${prefix}pitch_front_link" />
    <axis
      xyz="0 0 1" />
    <mimic joint="${prefix}pitch_back_joint" multiplier="1"/>
    <limit
      lower="-0.93556"
      upper="0.94249"
      effort="1000"
	  velocity="10" />
  </joint>

  <!-- link 13: pitch_front_link -->
  <link name="${prefix}remote_center_link"/>

  <!-- joint 13: pitch_front_joint -->
  <joint name="${prefix}remote_center_joint" type="fixed">
    <parent link="${prefix}base_link"/>
    <child link="${prefix}remote_center_link"/>
    <origin rpy="0 0 0" xyz="0 0.4864 0"/>
  </joint>

  </xacro:macro>
</robot>
